Workbook

Sheet Presupuesto
C1: Año: | D1: 2024
C2: Meses: | D2: 1 | E2: 2 | F2: 3 | G2: 4 | H2: 5 | I2: 6 | J2: 7 | K2: 8 | L2: 9 | M2: 10 | N2: 11 | O2: 12
A3: dpto | B3: ID_cuenta | C3: nomCta | D3: =$D$1&"-"&TEXT(D2,"00") -> 2024-01 | E3: =$D$1&"-"&TEXT(E2,"00") -> 2024-02 | F3: =$D$1&"-"&TEXT(F2,"00") -> 2024-03 | G3: =$D$1&"-"&TEXT(G2,"00") -> 2024-04 | H3: =$D$1&"-"&TEXT(H2,"00") -> 2024-05 | I3: =$D$1&"-"&TEXT(I2,"00") -> 2024-06 | J3: =$D$1&"-"&TEXT(J2,"00") -> 2024-07 | K3: =$D$1&"-"&TEXT(K2,"00") -> 2024-08 | ... O3: =$D$1&"-"&TEXT(O2,"00") -> 2024-12
A4: 00-Ventas | B4: =VALUE(LEFT(Presupuesto!$C4,3)&0) -> 7000 | C4: 700. Ventas de mercaderías | D4: 63373.5 | E4: 62123.01 | F4: 56364.53 | G4: 65569.81 | H4: 52460.94 | I4: 71488.98 | J4: 75329.85 | K4: 56735.94 | L4: 61594.62 | M4: 64608.96 | N4: 70026.09 | O4: 56997.66
A5: 00-Ventas | B5: =VALUE(LEFT(Presupuesto!$C5,3)&0) -> 7100 | C5: 710. Variación de existencias de productos en curso | O5: -200
A6: 00-Ventas | B6: =VALUE(LEFT(Presupuesto!$C6,3)&0) -> 7400 | C6: 740. Subvenciones, donaciones y legados a la explotación | D6: 3000 | E6: 3000 | J6: 3000
A7: 00-Ventas | B7: =VALUE(LEFT(Presupuesto!$C7,3)&0) -> 7600 | C7: 760. Ingresos de participaciones en instrumentos de patrimonio, empresas del grupo | G7: 14.42
A8: 00-Ventas | B8: =VALUE(LEFT(Presupuesto!$C8,3)&0) -> 7690 | C8: 769. Otros ingresos financieros | E8: 20 | F8: 0.03 | H8: 9.03 | I8: 28.17 | L8: 0.5 | M8: 50 | O8: 147.5
A10: 01-Producción | B10: =VALUE(LEFT(Presupuesto!$C10,3)&0) -> 6000 | C10: 600. Compras de mercaderías | D10: -40000 | E10: -40000 | F10: -40000 | G10: -40000 | H10: -40000 | I10: -40000 | J10: -40000 | K10: -40000 | L10: -40000 | M10: -40000 | N10: -40000 | O10: -40000
A11: 01-Producción | B11: =VALUE(LEFT(Presupuesto!$C11,3)&0) -> 6020 | C11: 602. Compras de otros aprovisionamientos | D11: -448.15 | E11: -1.99 | H11: -78.01 | J11: -64.35 | L11: -185.81 | M11: -134.63 | N11: -51.16 | O11: -64.02
A12: 01-Producción | B12: =VALUE(LEFT(Presupuesto!$C12,3)&0) -> 6100 | C12: 610. Variación de existencias de mercaderías | O12: 28530.26
A13: 01-Producción | B13: =VALUE(LEFT(Presupuesto!$C13,3)&0) -> 6220 | C13: 622. Reparaciones y conservación | D13: -90 | F13: -45.6 | G13: -34 | H13: -173.9 | J13: -409.45 | L13: -561.37 | M13: -670
A14: 01-Producción | B14: =VALUE(LEFT(Presupuesto!$C14,3)&0) -> 6400 | C14: 640. Sueldos y salarios | D14: -7751.816 | E14: -7751.816 | F14: -8087.679 | G14: -7830.19 | H14: -7908.564 | I14: -7908.564 | J14: -8621.298 | K14: -7909.851 | L14: -7953.444 | M14: -7899.528 | N14: -7888.019 | O14: -8560.086
A15: 01-Producción | B15: =VALUE(LEFT(Presupuesto!$C15,3)&0) -> 6420 | C15: 642. Seguridad Social a cargo de la empresa | D15: -183.149 | E15: -180.638 | F15: -183.149 | G15: -213.708 | H15: -197.484 | I15: -245.104 | J15: -246.767 | K15: -246.767 | L15: -193.218 | M15: -121.621 | N15: -228.793 | O15: -236.267
A16: 01-Producción | B16: =VALUE(LEFT(Presupuesto!$C16,3)&0) -> 6810 | C16: 681. Amortización del inmovilizado material | D16: 0 | E16: 0 | F16: 0 | G16: 0 | H16: 0 | I16: 0 | J16: 0 | K16: 0 | L16: 0 | M16: 0 | N16: 0 | O16: -429.0388
A18: 02-Finanzas | B18: =VALUE(LEFT(Presupuesto!$C18,3)&0) -> 6230 | C18: 623. Servicios de profesionales independientes | D18: -226.29 | E18: -1129.8 | F18: -640.52 | G18: -790.75 | H18: -525.94 | I18: -440.4 | J18: -440.4 | K18: -440.4 | L18: -440.4 | M18: -729.5 | N18: -440.4 | O18: -440.4
A19: 02-Finanzas | B19: =VALUE(LEFT(Presupuesto!$C19,3)&0) -> 6250 | C19: 625. Primas de seguros | D19: -643.11 | E19: -1537.63 | F19: 181.28 | G19: -535.22 | J19: -535.22 | K19: -1253.66 | M19: -967.42
A20: 02-Finanzas | B20: =VALUE(LEFT(Presupuesto!$C20,3)&0) -> 6260 | C20: 626. Servicios bancarios y similares | D20: -40.31 | E20: -92.11 | F20: -117.62 | G20: -28.73 | H20: -30.03 | I20: -353.19 | J20: -29.32 | K20: -47.7 | L20: -28.2 | M20: -367.6 | N20: -78.55 | O20: -74.8
A21: 02-Finanzas | B21: =VALUE(LEFT(Presupuesto!$C21,3)&0) -> 6300 | C21: 630. Impuesto corriente | O21: -905.89
A22: 02-Finanzas | B22: =VALUE(LEFT(Presupuesto!$C22,3)&0) -> 6310 | C22: 631. Otros tributos | H22: -112 | J22: -863.22 | M22: -942.9 | O22: 4000
A23: 02-Finanzas | B23: =VALUE(LEFT(Presupuesto!$C23,3)&0) -> 6380 | C23: 638. Ajustes positivos en la imposición sobre beneficios | O23: 1254.64
A24: 02-Finanzas | B24: =VALUE(LEFT(Presupuesto!$C24,3)&0) -> 6400 | C24: 640. Sueldos y salarios | D24: -2751.816 | E24: -2751.816 | F24: -3087.679 | G24: -2830.19 | H24: -2908.564 | I24: -2908.564 | J24: -3621.298 | K24: -2909.851 | L24: -2953.444 | M24: -2899.528 | N24: -2888.019 | O24: -3560.086
A25: 02-Finanzas | B25: =VALUE(LEFT(Presupuesto!$C25,3)&0) -> 6420 | C25: 642. Seguridad Social a cargo de la empresa | D25: -183.149 | E25: -180.638 | F25: -183.149 | G25: -213.708 | H25: -197.484 | I25: -245.104 | J25: -246.767 | K25: -246.767 | L25: -193.218 | M25: -121.621 | N25: -228.793 | O25: -236.267
A26: 02-Finanzas | B26: =VALUE(LEFT(Presupuesto!$C26,3)&0) -> 6590 | C26: 659. Otras pérdidas en gestión corriente
A27: 02-Finanzas | B27: =VALUE(LEFT(Presupuesto!$C27,3)&0) -> 6620 | C27: 662. Intereses de deudas, empresas del grupo | D27: -60.87 | E27: -83.47 | F27: -374.74 | G27: -43.05 | H27: -0.05 | I27: -334.2 | K27: -130.99 | M27: -249.98 | N27: -113.28 | O27: -230.29
A28: 02-Finanzas | B28: =VALUE(LEFT(Presupuesto!$C28,3)&0) -> 6650 | C28: 665. Intereses por descuento de efectos en otras entidades de crédito | D28: -128.77 | E28: -68.99 | F28: -107.79 | G28: -54.11 | H28: -60.33 | I28: -55.26 | J28: -69.98 | K28: -62.08 | L28: -80.01 | M28: -85.72 | N28: -92.23 | O28: -149.88
A29: 02-Finanzas | B29: 6653 | C29: 665. Intereses por descuento de efectos en otras entidades de crédito
A30: 02-Finanzas | B30: =VALUE(LEFT(Presupuesto!$C30,3)&0) -> 6690 | C30: 669. Otros gastos financieros | D30: -111.44 | E30: -405.02 | F30: -48.71 | G30: -204.76 | H30: -506.61 | I30: -46.99 | J30: -385.54 | K30: -342.42 | L30: -10.4 | M30: -359.02 | N30: -35.7 | O30: -11.92
A31: 02-Finanzas | B31: =VALUE(LEFT(Presupuesto!$C31,3)&0) -> 6810 | C31: 681. Amortización del inmovilizado material | O31: -4290.388
A32: 02-Finanzas | B32: =VALUE(LEFT(Presupuesto!$C32,3)&0) -> 6220 | C32: 622. Reparaciones y conservación | D32: -90 | F32: -45.6 | G32: -34 | H32: -173.9 | J32: -409.45 | L32: -561.37 | M32: -670
A34: 03-Comercial | B34: =VALUE(LEFT(Presupuesto!$C34,3)&0) -> 6240 | C34: 624. Transportes | D34: -208.83 | E34: -2057.79 | F34: -1389.3 | G34: -894.79 | H34: -1444.32 | I34: -3415.76 | J34: -951.2 | K34: -3574.93 | L34: -1960.37 | M34: -2839.64 | N34: -2045.22 | O34: -2721.58
A35: 03-Comercial | B35: =VALUE(LEFT(Presupuesto!$C35,3)&0) -> 6270 | C35: 627. Publicidad, propaganda y relaciones públicas | D35: -804.29 | E35: -5720.44 | F35: -117.4 | G35: -185 | H35: -204.8 | I35: -89.5 | J35: -475.12 | L35: -210 | M35: -105 | N35: -8303 | O35: -1689.81
A36: 03-Comercial | B36: =VALUE(LEFT(Presupuesto!$C36,3)&0) -> 6290 | C36: 629. Otros servicios | F36: -175 | O36: -9.92
A37: 03-Comercial | B37: =VALUE(LEFT(Presupuesto!$C37,3)&0) -> 6400 | C37: 640. Sueldos y salarios | D37: -751.816 | E37: -751.816 | F37: -1087.679 | G37: -830.19 | H37: -908.564 | I37: -908.564 | J37: -1621.298 | K37: -909.851 | L37: -953.444 | M37: -899.528 | N37: -888.019 | O37: -1560.086
A38: 03-Comercial | B38: =VALUE(LEFT(Presupuesto!$C38,3)&0) -> 6420 | C38: 642. Seguridad Social a cargo de la empresa | D38: -183.149 | E38: -180.638 | F38: -183.149 | G38: -213.708 | H38: -197.484 | I38: -245.104 | J38: -246.767 | K38: -246.767 | L38: -193.218 | M38: -121.621 | N38: -228.793 | O38: -236.267
A39: 03-Comercial | B39: =VALUE(LEFT(Presupuesto!$C39,3)&0) -> 6810 | C39: 681. Amortización del inmovilizado material | O39: -4290.388
A40: 03-Comercial | B40: =VALUE(LEFT(Presupuesto!$C40,3)&0) -> 6220 | C40: 622. Reparaciones y conservación | D40: -90 | F40: -45.6 | G40: -34 | H40: -173.9 | J40: -409.45 | L40: -561.37 | M40: -670
A41: 03-Comercial | B41: =VALUE(LEFT(Presupuesto!$C41,3)&0) -> 6280 | C41: 628. Suministros | D41: -1074.55 | E41: -792.97 | F41: -416.79 | G41: -1488.64 | H41: -589.92 | I41: -1148.21 | J41: -829.76 | K41: -897.21 | L41: -329.99 | M41: -1643.75 | N41: -1151.36 | O41: -1081.85
A43: 04-RRHH | B43: =VALUE(LEFT(Presupuesto!$C43,3)&0) -> 6400 | C43: 640. Sueldos y salarios | D43: -751.816 | E43: -751.816 | F43: -1087.679 | G43: -830.19 | H43: -908.564 | I43: -908.564 | J43: -1621.298 | K43: -909.851 | L43: -953.444 | M43: -899.528 | N43: -888.019 | O43: -1560.086
A44: 04-RRHH | B44: =VALUE(LEFT(Presupuesto!$C44,3)&0) -> 6420 | C44: 642. Seguridad Social a cargo de la empresa | D44: -183.149 | E44: -180.638 | F44: -183.149 | G44: -213.708 | H44: -197.484 | I44: -245.104 | J44: -246.767 | K44: -246.767 | L44: -193.218 | M44: -121.621 | N44: -228.793 | O44: -236.267
...
